{"uuid": "d57876bd-2125-4ab7-a50b-bbfd0a739fed", "children": ["297071ae-e4f7-4fc3-8de2-a64d16b1dcde"], "befores": [{"name": "setup", "status": "broken", "statusDetails": {"message": "selenium.common.exceptions.TimeoutException: Message: connection refused\n\n", "trace": "  File \"c:\\python37\\lib\\site-packages\\pluggy\\callers.py\", line 187, in _multicall\n    res = hook_impl.function(*args)\n  File \"c:\\python37\\lib\\site-packages\\_pytest\\fixtures.py\", line 964, in pytest_fixture_setup\n    result = call_fixture_func(fixturefunc, request, kwargs)\n  File \"c:\\python37\\lib\\site-packages\\_pytest\\fixtures.py\", line 788, in call_fixture_func\n    res = next(it)\n  File \"C:\\Users\\GOURAV\\PycharmProjects\\MultipleProjects\\TestCases\\conftest.py\", line 28, in setup\n    driver = Firefox(executable_path=path, options=firefox_opt)\n  File \"c:\\python37\\lib\\site-packages\\selenium\\webdriver\\firefox\\webdriver.py\", line 174, in __init__\n    keep_alive=True)\n  File \"c:\\python37\\lib\\site-packages\\selenium\\webdriver\\remote\\webdriver.py\", line 157, in __init__\n    self.start_session(capabilities, browser_profile)\n  File \"c:\\python37\\lib\\site-packages\\selenium\\webdriver\\remote\\webdriver.py\", line 252, in start_session\n    response = self.execute(Command.NEW_SESSION, parameters)\n  File \"c:\\python37\\lib\\site-packages\\selenium\\webdriver\\remote\\webdriver.py\", line 321, in execute\n    self.error_handler.check_response(response)\n  File \"c:\\python37\\lib\\site-packages\\selenium\\webdriver\\remote\\errorhandler.py\", line 242, in check_response\n    raise exception_class(message, screen, stacktrace)\n"}, "start": 1592458223747, "stop": 1592458287515}], "start": 1592458223747, "stop": 1592458298776}